The above exception was the direct cause of the following exception:

Traceback (most recent call last):
  File "/usr/local/lib/python3.12/site-packages/asgiref/sync.py", line 518, in thread_handler
    raise exc_info[1]
  File "/usr/local/lib/python3.12/site-packages/django/core/handlers/exception.py", line 42, in inner
    response = await get_response(request)
               ^^^^^^^^^^^^^^^^^^^^^^^^^^^
  File "/usr/local/lib/python3.12/site-packages/asgiref/sync.py", line 518, in thread_handler
    raise exc_info[1]
  File "/usr/local/lib/python3.12/site-packages/django/core/handlers/base.py", line 253, in _get_response_async
    response = await wrapped_callback(
               ^^^^^^^^^^^^^^^^^^^^^^^
  File "/usr/local/lib/python3.12/site-packages/asgiref/sync.py", line 468, in __call__
    ret = await asyncio.shield(exec_coro)
          ^^^^^^^^^^^^^^^^^^^^^^^^^^^^^^^
  File "/usr/local/lib/python3.12/site-packages/asgiref/current_thread_executor.py", line 40, in run
    result = self.fn(*self.args, **self.kwargs)
             ^^^^^^^^^^^^^^^^^^^^^^^^^^^^^^^^^^
  File "/usr/local/lib/python3.12/site-packages/asgiref/sync.py", line 522, in thread_handler
    return func(*args, **kwargs)
           ^^^^^^^^^^^^^^^^^^^^^
  File "/usr/local/lib/python3.12/site-packages/django/views/decorators/csrf.py", line 65, in _view_wrapper
    return view_func(request, *args, **kwargs)
           ^^^^^^^^^^^^^^^^^^^^^^^^^^^^^^^^^^^
  File "/usr/local/lib/python3.12/site-packages/django/views/generic/base.py", line 105, in view
    return self.dispatch(request, *args, **kwargs)
           ^^^^^^^^^^^^^^^^^^^^^^^^^^^^^^^^^^^^^^^
  File "/usr/local/lib/python3.12/site-packages/rest_framework/views.py", line 515, in dispatch
    response = self.handle_exception(exc)
               ^^^^^^^^^^^^^^^^^^^^^^^^^^
  File "/usr/local/lib/python3.12/site-packages/rest_framework/views.py", line 475, in handle_exception
    self.raise_uncaught_exception(exc)
  File "/usr/local/lib/python3.12/site-packages/rest_framework/views.py", line 486, in raise_uncaught_exception
    raise exc
  File "/usr/local/lib/python3.12/site-packages/rest_framework/views.py", line 512, in dispatch
    response = handler(request, *args, **kwargs)
               ^^^^^^^^^^^^^^^^^^^^^^^^^^^^^^^^^
  File "/usr/local/lib/python3.12/site-packages/rest_framework/generics.py", line 212, in get
    return self.retrieve(request, *args, **kwargs)
           ^^^^^^^^^^^^^^^^^^^^^^^^^^^^^^^^^^^^^^^
  File "/usr/local/lib/python3.12/site-packages/rest_framework/mixins.py", line 54, in retrieve
    instance = self.get_object()
               ^^^^^^^^^^^^^^^^^
  File "/app/users/views.py", line 25, in get_object
    profile = get_object_or_404(
              ^^^^^^^^^^^^^^^^^^
  File "/usr/local/lib/python3.12/site-packages/django/shortcuts.py", line 90, in get_object_or_404
    return queryset.get(*args, **kwargs)
           ^^^^^^^^^^^^^^^^^^^^^^^^^^^^^
  File "/usr/local/lib/python3.12/site-packages/django/db/models/query.py", line 629, in get
    num = len(clone)
          ^^^^^^^^^^
  File "/usr/local/lib/python3.12/site-packages/django/db/models/query.py", line 366, in __len__
^C    self._fetch_all()
  File "/usr/local/lib/python3.12/site-packages/django/db/models/query.py", line 1949, in _fetch_all
    self._result_cache = list(self._iterable_class(self))
                         ^^^^^^^^^^^^^^^^^^^^^^^^^^^^^^^^
  File "/usr/local/lib/python3.12/site-packages/django/db/models/query.py", line 91, in __iter__
    results = compiler.execute_sql(
              ^^^^^^^^^^^^^^^^^^^^^
  File "/usr/local/lib/python3.12/site-packages/django/db/models/sql/compiler.py", line 1621, in execute_sql
    cursor = self.connection.cursor()
             ^^^^^^^^^^^^^^^^^^^^^^^^
  File "/usr/local/lib/python3.12/site-packages/django/utils/asyncio.py", line 26, in inner
    return func(*args, **kwargs)
           ^^^^^^^^^^^^^^^^^^^^^
  File "/usr/local/lib/python3.12/site-packages/django/db/backends/base/base.py", line 320, in cursor
    return self._cursor()
           ^^^^^^^^^^^^^^
  File "/usr/local/lib/python3.12/site-packages/django/db/backends/base/base.py", line 296, in _cursor
    self.ensure_connection()
  File "/usr/local/lib/python3.12/site-packages/django/utils/asyncio.py", line 26, in inner
    return func(*args, **kwargs)
           ^^^^^^^^^^^^^^^^^^^^^
  File "/usr/local/lib/python3.12/site-packages/django/db/backends/base/base.py", line 278, in ensure_connection
    with self.wrap_database_errors:
         ^^^^^^^^^^^^^^^^^^^^^^^^^
  File "/usr/local/lib/python3.12/site-packages/django/db/utils.py", line 91, in __exit__
    raise dj_exc_value.with_traceback(traceback) from exc_value
  File "/usr/local/lib/python3.12/site-packages/django/db/backends/base/base.py", line 279, in ensure_connection
    self.connect()
  File "/usr/local/lib/python3.12/site-packages/django/utils/asyncio.py", line 26, in inner
    return func(*args, **kwargs)
           ^^^^^^^^^^^^^^^^^^^^^
  File "/usr/local/lib/python3.12/site-packages/django/db/backends/base/base.py", line 256, in connect
    self.connection = self.get_new_connection(conn_params)
                      ^^^^^^^^^^^^^^^^^^^^^^^^^^^^^^^^^^^^
  File "/usr/local/lib/python3.12/site-packages/django/utils/asyncio.py", line 26, in inner
    return func(*args, **kwargs)
           ^^^^^^^^^^^^^^^^^^^^^
  File "/usr/local/lib/python3.12/site-packages/django/db/backends/postgresql/base.py", line 332, in get_new_connection
    connection = self.Database.connect(**conn_params)
                 ^^^^^^^^^^^^^^^^^^^^^^^^^^^^^^^^^^^^
  File "/usr/local/lib/python3.12/site-packages/psycopg2/__init__.py", line 122, in connect
    conn = _connect(dsn, connection_factory=connection_factory, **kwasync)
           ^^^^^^^^^^^^^^^^^^^^^^^^^^^^^^^^^^^^^^^^^^^^^^^^^^^^^^^^^^^^^^^
django.db.utils.OperationalError: connection to server at "db" (172.18.0.2), port 5432 failed: FATAL:  sorry, too many clients already

